Workbook

Sheet Summ of Fund Requisitions
A1: Fund Requisition Form
A3: Requisition Period: | B3: ${claimVO.claimStartAndEndYear} | F3: Principal Investigator: | G3: ${claimVO.claim.rdoName}
A4: LA/Contract No.: | B4: ${claimVO.claim.award.sponsorAwardNumber} | F4: Host Institution: | G4: Nanyang Technological University
A5: Project Title: | B5: ${claimVO.claim.award.title}
A6: Qualifying Period: | B6: ${claimVO.awardStartDate} | C6: (Project Commencement Date) to | E6: ${claimVO.awardEndDate} | F6: (Project Completion Date)
A7: Project Duration: | B7: ${claimVO.claim.award.durationInMonths}
A9: 1. SUMMARY OF FUND REQUISITION
B11: Awarded | C11: Cumulative Disbursement up to Previous Quarter* | F11: Disbursement for the Current Quarter
A12: Cost Item | B12: Grant Amount | C12: Actual Cost Incurred | D12: Amount Disbursed | E12: Remaining Grant Balance | F12: Actual Cost Incurred | G12: Claim Amount | H12: Remarks
B13: $ | C13: $ | D13: $ | E13: $ | F13: $ | G13: $
A14: (a) Expenditure on Manpower (EOM)
A15: i) Salary (Local Manpower) | B15: ${summary.latestApprovedBudget} | C15: ${summary.cumExpenseUptoPrevClaim} | D15: =C15 -> ${summary.cumExpenseUptoPrevClaim} | E15: =B15-D15-D16 -> #VALUE! | F15: =EOM!J9 -> 0 | G15: =EOM!L9 -> #VALUE!
A16: ii) Salary (Foreign Manpower) | D16: =C16 -> 0 | F16: =EOM!J12 -> $[SUM(U_(J11))] | G16: =EOM!L12 -> $[SUM(U_(L11))]
A17: Total for (a) | B17: =SUM(B15:B16) -> 0 | C17: =SUM(C15:C16) -> 0 | D17: =SUM(D15:D16) -> 0 | E17: =B17-D17 -> 0 | F17: =SUM(F15:F16) -> 0 | G17: =SUM(G15:G16) -> #VALUE!
A18: (b) Equipment
A19: i) Equipment | B19: ${summary.latestApprovedBudget} | C19: ${summary.cumExpenseUptoPrevClaim} | D19: =C19 -> ${summary.cumExpenseUptoPrevClaim} | E19: =B19-D19 -> #VALUE! | F19: =Equipment!F6 -> 0 | G19: =Equipment!H6 -> #VALUE!
A20: Total for (b) | B20: =SUM(B19:B19) -> 0 | C20: =SUM(C19:C19) -> 0 | D20: =SUM(D19:D19) -> 0 | E20: =B20-D20 -> 0 | F20: =F19 -> 0 | G20: =G19 -> #VALUE!
A21: (c) Other Operating Expenses (OOE)
A22: i) Materials and Consumables | B22: ${summary.latestApprovedBudget} | C22: ${summary.cumExpenseUptoPrevClaim} | D22: =C22 -> ${summary.cumExpenseUptoPrevClaim} | E22: =B22-D22 -> #VALUE! | F22: =OOE!F8 -> 0 | G22: =OOE!H8 -> #VALUE!
A23: ii) Software | B23: 0 | C23: 0 | D23: 0 | E23: =B23-D23 -> 0 | F23: =OOE!F24 -> 0 | G23: =OOE!H24 -> 0
A24: ii) Other Costs | B24: ${summary.latestApprovedBudget} | C24: ${summary.cumExpenseUptoPrevClaim} | D24: =C24 -> ${summary.cumExpenseUptoPrevClaim} | E24: =B24-D24 -> #VALUE! | F24: =OOE!F37 -> 0 | G24: =OOE!H37 -> #VALUE!
A25: Total for (c) | B25: =SUM(B22:B24) -> 0 | C25: =SUM(C22:C24) -> 0 | D25: =SUM(D22:D24) -> 0 | E25: =B25-D25 -> 0 | F25: =SUM(F22:F24) -> 0 | G25: =SUM(G22:G24) -> #VALUE!
A26: (d) Overseas Travel
A27: i) Overseas Travel | B27: ${summary.latestApprovedBudget} | C27: ${summary.cumExpenseUptoPrevClaim} | D27: =C27 -> ${summary.cumExpenseUptoPrevClaim} | E27: =B27-D27 -> #VALUE! | F27: ='Overseas Travel'!E6 -> 0 | G27: ='Overseas Travel'!G6 -> #VALUE!
A28: Total for (d) | B28: =SUM(B27:B27) -> 0 | C28: =SUM(C27:C27) -> 0 | D28: =SUM(D27:D27) -> 0 | E28: =B28-D28 -> 0 | F28: =F27 -> 0 | G28: =G27 -> #VALUE!
A29: (e) Research Scholarship
A30: i) Research Scholarship | B30: ${summary.latestApprovedBudget} | C30: ${summary.cumExpenseUptoPrevClaim} | D30: =C30 -> ${summary.cumExpenseUptoPrevClaim} | E30: =B30-D30 -> #VALUE! | F30: ='Research Scholarship'!H6 -> 0 | G30: ='Research Scholarship'!J6 -> #VALUE!
A31: Total for (e) | B31: =SUM(B30:B30) -> 0 | C31: =SUM(C30:C30) -> 0 | D31: =SUM(D30:D30) -> 0 | E31: =B31-D31 -> 0 | F31: =F30 -> 0 | G31: =G30 -> #VALUE!
A32: (f) Indirect Costs
A33: i) Overheads (= ${claimVO.oHPercentage}% of (a+b+c+d)) | B33: {=ROUND(SUM(B17,B20,B25,B28,B31)*SUMPRODUCT(MID(0&A33, LARGE(INDEX(ISNUMBER(--MID(A33, ROW(INDIRECT("1:"&LEN(A33))), 1)) * ROW(INDIRECT("1:"&LEN(A33))), 0), ROW(INDIRECT("1:"&LEN(A33))))+1, 1) * 10^ROW(INDIRECT("1:"&LEN(A33)))/10)%, 2)} -> 0 | D33: {=ROUND(SUM(D17,D20,D25,D28,D31)*SUMPRODUCT(MID(0&A33, LARGE(INDEX(ISNUMBER(--MID(A33, ROW(INDIRECT("1:"&LEN(A33))), 1)) * ROW(INDIRECT("1:"&LEN(A33))), 0), ROW(INDIRECT("1:"&LEN(A33))))+1, 1) * 10^ROW(INDIRECT("1:"&LEN(A33)))/10)%, 2)} -> 0 | E33: =B33-D33 -> 0 | G33: ='Indirect Costs'!C19 -> #VALUE!
A34: Total for (f) | B34: =B33 -> 0 | D34: =D33 -> 0 | E34: =B34-D34 -> 0 | G34: =G33 -> #VALUE!
A35: GRAND TOTAL (a+b+c+d+e+f) | B35: =B17+B20+B25+B28+B31+B34 -> 0 | C35: =C17+C20+C25+C28+C31 -> 0 | D35: =D17+D20+D25+D28+D31+D34 -> 0 | E35: =E17+E20+E25+E28+E31+E34 -> 0 | F35: =F17+F20+F25+F28+F31 -> 0 | G35: =G17+G20+G25+G28+G31+G34 -> #VALUE! | H35: Cumulative disbursement as a % of Grant Amount including current claims | L35: =(G35+D35)/B35 -> #VALUE!
A36: Rounded Down
A37: * "Cumulative Disbursement" refers to the cumulative actual project costs incurred and grant funds disbursed until the end of the previous quarter, excluding the claim amount requested for the current quarter.
A39: We hereby certify that the statement and the accompanying supporting documents are correct and according to the terms and conditions of the grant, and that they have been verified to
A40: their original source documents. We confirm that, inclusive of this claim, the cumulative amounts claimed do not exceed the allocated grant for each individual line item listed in
A41: Appendix B (Grant Details) of the Letter of Award. We also certify that we have not sought, and will not seek, reimbursement for the same item of expenditure under
A42: any other incentives from any other government agencies. | H42: For Official Use :
H43: Checked & verifed by
A46: Signature : | D46: Signature :
...

Sheet EOM
A1: 2. BREAKDOWN
A3: (a) EOM
A5: S/No. | B5: Name of Researcher | C5: Organisation | D5: Designation | E5: Overall Project Involvement Period | F5: Monthly Basic | G5: Employer CPF | H5: Other Costs | I5: Involvement period for current claim | J5: Actual Cost Incurred | K5: *Level of Support | L5: Claim Amount = (o) x (p) | M5: Item Code / Remarks
E6: DDMMYY - DDMMYY | F6: $ | G6: $ | H6: $ | I6: DDMMYY - DDMMYY | J6: (o) $ | K6: (p) % | L6: $
B7: (i) Local Manpower
A8: ${ind+1} | B8: ${gTransactions.items[0].manpowerFullName} | C8: ${manpwr.department} | D8: ${gTransactions.items[0].manpowerJobDescription} | E8: ${date.formatter("dd/MM/yyyy").format(manpwr.items[0].chargeStartDate)} - ${date.formatter("dd/MM/yyyy").format(manpwr.items[manpwr.items.size()-1].chargeEndDate)} | F8: ${transactions.descriptionOfExpenditure == "Monthly Rate"? transactions.qualifyingCost:0.00} | G8: ${transactions.descriptionOfExpenditure == "Employer CPF"? transactions.qualifyingCost:" "} | H8: ${transactions.descriptionOfExpenditure != "Monthly Rate" && transactions.descriptionOfExpenditure != "Employer CPF"? transactions.qualifyingCost:0.00} | I8: ${date.formatter("dd/MM/yyyy").format(claimVO.claim.startDate)} - ${date.formatter("dd/MM/yyyy").format(claimVO.claim.endDate)} | J8: =SUM(F8:H8) -> 0 | K8: ${transactions.levelOfSupportPercentage} | L8: =J8*K8% -> #VALUE! | M8: ${transactions.descriptionOfExpenditure}
I9: Sub-total for (i) | J9: =SUM(J8:J8) -> 0 | L9: =SUM(L8:L8) -> #VALUE!
B10: (ii) Foreign Manpower
A11: ${ind+1} | B11: ${gTransactions.items[0].manpowerFullName} | C11: ${manpwr.department} | D11: ${gTransactions.items[0].manpowerJobDescription} | E11: ${date.formatter("dd/MM/yyyy").format(manpwr.items[0].chargeStartDate)} - ${date.formatter("dd/MM/yyyy").format(manpwr.items[manpwr.items.size()-1].chargeEndDate)} | F11: ${transactions.descriptionOfExpenditure == "Monthly Rate"? transactions.qualifyingCost:0.00} | H11: ${transactions.descriptionOfExpenditure != "Monthly Rate" && transactions.descriptionOfExpenditure != "Employer CPF"? transactions.qualifyingCost:0.00} | I11: ${date.formatter("dd/MM/yyyy").format(claimVO.claim.startDate)} - ${date.formatter("dd/MM/yyyy").format(claimVO.claim.endDate)} | J11: =F11+H11 -> #VALUE! | K11: ${transactions.levelOfSupportPercentage} | L11: =J11*K11% -> #VALUE! | M11: ${transactions.descriptionOfExpenditure}
I12: Sub-total for (ii) | J12: $[SUM(U_(J11))] | L12: $[SUM(U_(L11))]
A13: *Please refer to points (2) and (3) under Important Notes for EOM (Table 2a)
B15: Qualifying items | C15: Actual Cost Incurred | D15: Claim Amount
B16: Total for (a) = (i)+(ii) | C16: =J9+J12 -> #VALUE! | D16: =L9+L12 -> #VALUE!
A18: Important Notes:
A19: 1. Only for qualifying cost items provided for in the approved grant by EMA. Indicate in the Remarks column the Item Code of the approved EOM item as stated in Appendix B of the Letter of Award.
A20: 2. For all cost categories (i.e. EOM, Equipment, OOE, Overseas Travel and Research Scholarship), the level of support is prescribed as follows - Qualifying direct costs incurred by Institutes of Higher Learning (IHLs), public sector agencies and not-for-profit organisations will be supported at 100%, while qualifying directs costs incurred by companies and company-affiliated research entities will be supported at 70%.
A21: 3. For EOM, the level of support also includes the Researcher's level of involvement in the project. E.g. if the Researcher spends 30% of his/her time on the project, the level of support for the cost item will be reduced by an additional 70%. If the Researcher's level of involvement is less than 100%, please indicate the level of involvement in the Remarks column.
A22: 4. All Names, Designations and Overall Project Involvement Periods for every Researcher should agree with Form 1b. Form 1b must be submitted when there is a new hire.
A23: 5. Please include payslips, payroll records and records that show posting of payroll amounts to the General Ledger (e.g. Accounting Transactions Reports) for all EOM claims detailed above. EMA may request for additional supporting documents for the claims.
A24: 6. EOM components supportable under the EP grant are as prescribed in the prevailing version of the EP Guidelines.

Sheet Equipment
A1: (b) Equipment
A3: S/No. | B3: Qualifying Items | C3: Invoice Date | D3: Unit Purchase Cost | E3: Quantity | F3: Actual Cost Incurred | G3: *Level of Support | H3: Claim Amount = (o) x (p) | I3: Item Code / Remarks
C4: DDMMYY | D4: $ | F4: (o) $ | G4: (p) % | H4: $
A5: ${index+1} | B5: ${transactions.descriptionOfExpenditure} | C5: ${transactions.invoiceDate} | D5: ${transactions.unitPrice} | F5: ${transactions.totalAmount} | G5: ${transactions.levelOfSupportPercentage} | H5: =F5*G5% -> #VALUE! | I5: ${transactions.descriptionOfExpenditure}
E6: Sub-total | F6: =SUM(F5:F5) -> 0 | H6: =SUM(H5:H5) -> #VALUE!
A7: *Please refer to point (2) under Important Notes for EOM (Table 2a) and point (2) under Important Notes for Equipment (Table 2b)
B9: Qualifying items | C9: Actual Cost Incurred | E9: Claim Amount
B10: Total for (b) | C10: =F6 -> 0 | E10: =H6 -> #VALUE!
A12: Important Notes:
A13: 1. Only for qualifying cost items provided for in the approved grant by EMA. Indicate in the Remarks column the Item Code of the approved equipment cost item as stated in the Appendix B of the Letter of Award.
A14: 2. Please include soft copies of invoices of equipment ≥ $5,000. EMA may request for additional copies of other invoices.
A15: 3. Any equipment purchased and costs associated with the equipment purchase must be directly related to the project work. Equipment components supportable under the EP grant are as prescribed in the prevailing version of the EP Guidelines.

Sheet OOE
A1: (c) Other Operating Expenses (OOE)
A3: (i) Materials and Consumables
A5: S/No. | B5: Qualifying Items | C5: Invoice Date | D5: Unit Purchase Cost | E5: Quantity | F5: Actual Cost Incurred | G5: *Level of Support | H5: Claim Amount = (o) x (p) | I5: Item Code / Remarks
C6: DDMMYY | D6: $ | F6: (o) $ | G6: (p) % | H6: $
A7: ${index+1} | B7: ${transactions.descriptionOfExpenditure} | C7: ${transactions.invoiceDate} | F7: ${transactions.totalAmount} | G7: ${transactions.levelOfSupportPercentage} | H7: =F7*G7% -> #VALUE! | I7: ${transactions.descriptionOfExpenditure}
E8: Sub-total for (i) | F8: =SUM(F7:F7) -> 0 | H8: =SUM(H7:H7) -> #VALUE!
A9: *Please refer to point (2) under Important Notes for EOM (Table 2a)
A11: Important Notes:
A12: 1. Only for qualifying cost items provided for in the approved grant by EMA. Indicate in the Remarks column the Item Code of the approved OOE cost item as stated in Appendix B of the Letter of Award.
A13: 2. Please include soft copies of invoices ≥ $1,000. EMA may request for additional copies of other invoices.
A14: 3. OOE components supportable under the EP grant are as prescribed in the prevailing version of the EP Guidelines.
A16: (ii) Software
A18: S/No. | B18: Qualifying Items | C18: Invoice Date | D18: Unit Purchase Cost | E18: Quantity | F18: Actual Cost Incurred | G18: *Level of Support | H18: Claim Amount = (o) x (p) | I18: Item Code / Remarks
C19: DDMMYY | D19: $ | F19: (o) $ | G19: (p) % | H19: $
B20: [Name and description] | F20: =D20*E20 -> 0 | H20: =F20*G20 -> 0
F21: =D21*E21 -> 0 | H21: =F21*G21 -> 0
F22: =D22*E22 -> 0 | H22: =F22*G22 -> 0
F23: =D23*E23 -> 0 | H23: =F23*G23 -> 0
E24: Sub-total for (ii) | F24: =SUM(F20:F23) -> 0 | H24: =SUM(H20:H23) -> 0
A25: *Please refer to point (2) under Important Notes for EOM (Table 2a) and point (2) under Important Notes for Software (Table 2cii)
A27: Important Notes:
A28: 1. Only for qualifying cost items provided for in the approved grant by EMA. Indicate in the Remarks column the Item Code of the approved OOE cost item as stated in Appendix B of the Letter of Award.
A29: 2. Please include soft copies of invoices ≥ $1,000. EMA may request for additional copies of other invoices.
A30: 3. Any software purchased and costs associated with the software purchase must be directly related to the project work. OOE components supportable under the EP grant are as prescribed in the prevailing version of the EP Guidelines.
A32: (iii) Other Costs
A34: S/No. | B34: Qualifying Items | C34: Related Company? (if Y, indicate name) | E34: Invoice Date | F34: Actual Cost Incurred | G34: *Level of Support | H34: Claim Amount = (o) x (p) | I34: Item Code / Remarks
C35: Y/N/NA | E35: DDMMYY | F35: (o) $ | G35: (p) % | H35: $
A36: ${index+1} | B36: ${transactions.descriptionOfExpenditure} | E36: ${transactions.invoiceDate} | F36: ${transactions.totalAmount} | G36: ${transactions.levelOfSupportPercentage} | H36: =F36*G36% -> #VALUE! | I36: ${transactions.descriptionOfExpenditure}
E37: Sub-total for (ii) | F37: =SUM(F36:F36) -> 0 | H37: =SUM(H36:H36) -> #VALUE!
A38: *Please refer to point (2) under Important Notes for EOM (Table 2a)
A40: Important Notes:
A41: 1. Only for qualifying cost items provided for in the approved grant by EMA. Indicate in the Remarks column the Item Code of the approved OOE cost item as stated in Appendix B of the Letter of Award.
A42: 2. Manpower related costs that fall under OOE include visiting professors/experts and professional fees.
A43: 3. For Visiting Professors, please include as supporting documents (i) letter of offer clearly stating the amount to be paid to the Visiting Professor, (ii) hotel and airfare bills, (iii) documents showing the justification for engaging the Visiting Professor, and (iv) proof of payment to the Visiting Professor, showing the amount to be paid in SGD, foreign currency, exchange rate, bank charges etc.
A44: 4. For publication page charges for journal papers or additional pages in conference papers, please indicate (i) number of papers to be published / presented and (ii) cost of publishing per paper in the description. Please also submit soft copies of the papers published / presented.
A45: 5. Please include soft copies of invoices ≥ $1,000. EMA may request for additional copies of other invoices.
A46: 6. OOE components supportable under the EP grant are as prescribed in the prevailing version of the EP Guidelines.
B49: Qualifying items | C49: Actual Cost Incurred | E49: Claim Amount
B50: Total for (c) = (i)+(ii)+(ii) | C50: =F8+F24+F37 -> 0 | E50: =H8+H24+H37 -> #VALUE!

Sheet Overseas Travel
A1: (d) Overseas Travel
A3: S/No. | B3: Name of Researcher | C3: Destination/Purpose | D3: Date of Travel | E3: Actual Cost Incurred | F3: *Level of Support | G3: Claim Amount = (o) x (p) | H3: Item Code / Remarks
D4: DDMMYY - DDMMYY | E4: (o) $ | F4: (p) % | G4: $
A5: ${index+1} | B5: ${transactions.descriptionOfExpenditure} | D5: ${transactions.periodOfVisit} | E5: ${transactions.totalAmount} | F5: ${transactions.levelOfSupportPercentage} | G5: =E5*F5% -> #VALUE! | H5: ${transactions.descriptionOfExpenditure}
D6: Sub-total | E6: =SUM(E5:E5) -> 0 | G6: =SUM(G5:G5) -> #VALUE!
A7: *Please refer to point (2) under Important Notes for EOM (Table 2a)
B9: Qualifying items | C9: Actual Cost Incurred | D9: Claim Amount
B10: Total for (d) | C10: =E6 -> 0 | D10: =G6 -> #VALUE!
A12: Important Notes:
A13: 1. Only for qualifying cost items provided for in the approved grant by EMA. Indicate in the Remarks column the Item Code of the approved overseas travel cost item as stated in Appendix B of the Letter of Award.
A14: 2. For all overseas travel-related expenses and cost of living allowances, the organisation’s policy must be consistently adhered to and organisations may be requested to certify that such payments are in accordance with its formal policy.
A15: 3. Overseas conferences should be directly relevant and necessary to accomplish the project milestones/deliverables for the Principal Investigator, Co-Investigators and research staff funded under the project grant. Students’ expenses are not supported unless they are PhD students who are presenting papers.
A16: 4. Please include as supporting documents: (i) invitation letters/registration forms of the event/workshop/conference, (ii) email approval from Host Institution for the trip, (iii) air tickets (including boarding passes etc. to show it is economy class, and justifications for the purchase of air tickets if the travel dates are longer than the event dates), (v) hotel and conference fee bills, stating the amount in foreign currency and conversion to SGD (or proof of payment in SGD), (vi) documentation to support subsistence allowance for the trip, (vii) documentation to support land transport expenses, (viii) papers presented at the event/workshop/conference (where applicable), and (ix) any other documentation perceived necessary to support the expenses (e.g. visa fees etc.).
A17: 5. Please include soft copies of invoices ≥ $1,000. EMA may request for additional copies of other invoices.
A18: 6. Overseas Travel components supportable under the EP grant are as prescribed in the prevailing version of the EP Guidelines.

Sheet Research Scholarship
A1: (e) Research Scholarship
A3: S/No. | B3: Name of Scholar | C3: Organisation | D3: Designation | E3: Overall Project Involvement Period | F3: Monthly Cost | G3: Involvement period for current claim | H3: Actual Cost Incurred | I3: *Level of Support | J3: Claim Amount = (o) x (p) | K3: Item Code / Remarks
E4: DDMMYY - DDMMYY | F4: $ | G4: DDMMYY - DDMMYY | H4: (o) $ | I4: (p) % | J4: $
A5: ${index+1} | B5: ${transaction.manpowerFullName} | C5: ${transaction.manpower.department} | D5: ${transaction.manpowerJobDescription} | E5: ${date.formatter("dd/MM/yyyy").format(claimVO.claim.award.beginDate)} - ${date.formatter("dd/MM/yyyy").format(claimVO.claim.award.finalExpirationDate)} | G5: ${transactions.involvementPeriod} | H5: ${transactions.totalAmount} | I5: ${transactions.levelOfSupportPercentage} | J5: =H5*I5% -> #VALUE! | K5: ${transactions.descriptionOfExpenditure}
G6: Sub-total | H6: =SUM(H5:H5) -> 0 | J6: =SUM(J5:J5) -> #VALUE!
A7: *Please refer to point (2) under Important Notes for EOM (Table 2a) and point (2) under Important Notes for Research Scholarship (Table 2e)
B9: Qualifying items | C9: Actual Cost Incurred | E9: Claim Amount
B10: Total for (e) | C10: =H6 -> 0 | E10: =J6 -> #VALUE!
A12: Important Notes:
A13: 1. Only for qualifying cost items provided for in the approved grant by EMA. Indicate in the Remarks column the Item Code of the approved research scholarship cost item as stated in Appendix B of the Letter of Award.
A14: 2. For Research Scholarship, the level of support also includes the Scholar's level of involvement in the project. E.g. if the Scholar spends 30% of his/her time on the project, the level of support for the cost item will be reduced by an additional 70%. If the Scholar's level of involvement is less than 100%, please indicate the level of involvement in the Remarks column.
A15: 3. Postgraduate stipend must align with the prevailing rates set by the Ministry of Education. Postgraduate stipend and tuition support will not attract indirect costs.
A16: 4. Undergraduate stipend and tuition support are not allowable.
A17: 5. Please include relevant supporting document for all research scholarship claims detailed above. EMA may request for additional supporting documents for the claims.
A18: 6. Research Scholarship components supportable under the EP grant are as prescribed in the prevailing version of the EP Guidelines.

Sheet Indirect Costs
A1: (f) Indirect Costs (Overheads)
A3: S/No. | B3: Description | C3: Total Qualifying Direct Costs submitted in this claim | D3: *Level of Support | E3: Claim Amount = (o) x (p) | F3: Remarks
C4: (o) $ | D4: (p) % | E4: $
A5: 1 | B5: EOM | C5: ${summary.amountRequested} | D5: ${claimVO.oHPercentage}% | E5: =C5*D5 -> #VALUE!
A6: 2 | B6: Equipment | C6: ${summary.amountRequested} | D6: ${claimVO.oHPercentage}% | E6: =C6*D6 -> #VALUE!
A7: 3 | B7: OOE | C7: ${claimVO.summaryOOE_MACSumValues.amountRequestedForOOEMAC} | D7: ${claimVO.oHPercentage}% | E7: =C7*D7 -> #VALUE!
A8: 4 | B8: Overseas Travel | C8: ${summary.amountRequested} | D8: ${claimVO.oHPercentage}% | E8: =C8*D8 -> #VALUE!
D9: Sub-total | E9: =SUM(E5:E8) -> #VALUE!
A10: *Please refer to point (2) under Important Notes for Indirect Costs (Overheads) (Table 2f)
A12: Important Notes:
A13: 1. Only qualifying cost items provided for in the approved grant by EMA shall be considered in the Total Qualifying Direct Costs submitted in this claim.
A14: 2. Support for indirect costs is allowed only to Singapore-based Institutes of Higher Learning and not-for-profit entities.
A15: 3. Indirect Costs components supportable under the EP grant are as prescribed in the prevailing version of the EP Guidelines.
B18: Qualifying items | C18: Claim Amount
B19: Total for (f) | C19: =E9 -> #VALUE!

Sheet Cumulative Amt Claimed to Date
A1: (g) Cumulative Amount Claimed to Date
I2: For reference
A3: A. EOM | F3: Cumulative Disbursement up to Previous Quarter (S$) | G3: Claim Amount for Current Quarter (S$) | H3: Cumulative Claim Amount To-Date (S$) | I3: Cumulative Claims Amount To-Date (S$) | J3: Remaining Grant Balance (S$) | L3: ${date.formatter("MMM").format(claim.items[0].startDate)} - ${date.formatter("MMM yy").format(claim.items[0].endDate)} (S$)
A4: Item Code | B4: Staff Category | C4: Quantity | D4: Unit Cost / Head / Year | E4: Subtotal (S$)
D5: (S$)
A6: A-${index+1} | B6: ${summary.internalOrderCode.substring(15,20)} | E6: ${summary.approvedBudget} | F6: ${index==0?summary.groupedTransactions[0].transactions[0].claimSummary.cumExpenseUptoPrevPeriod:""} | G6: ${summary.quarterAdjustedTotal} | H6: =SUM(F6:G6) -> 0 | J6: =E6-H6 -> #VALUE!
A7: Total | E7: ='Summ of Fund Requisitions'!B17 -> 0 | F7: =SUM(F6:F6) -> 0 | G7: =SUM(G6:G6) -> 0 | H7: =SUM(H6:H6) -> 0 | I7: =SUM(I6:I6) -> 0 | J7: =E7-H7 -> 0 | L7: ${summary.quarterTotalAmount?summary.quarterTotalAmount:0.00}
A9: B. EQUIPMENT | F9: Cumulative Disbursement up to Previous Quarter | G9: Claim Amount for Current Quarter | H9: Cumulative Claim Amount To-Date (S$) | I9: Cumulative Claims Amount To-Date (S$) | J9: Remaining Grant Balance (S$) | L9: ${date.formatter("MMM").format(claim.items[0].startDate)} - ${date.formatter("MMM yy").format(claim.items[0].endDate)} (S$)
A10: Item Code | B10: Item Description | C10: Quantity | D10: Unit Cost | E10: Subtotal (S$)
D11: (S$)
A12: B-${index+1} | B12: ${summary.internalOrderCode.substring(15,20)} | E12: ${summary.approvedBudget} | F12: ${index==0?summary.groupedTransactions[0].transactions[0].claimSummary.cumExpenseUptoPrevPeriod:""} | G12: ${summary.quarterAdjustedTotal} | H12: =SUM(F12:G12) -> 0 | J12: =E12-H12 -> #VALUE!
A13: Total | E13: ='Summ of Fund Requisitions'!B20 -> 0 | F13: =SUM(F12:F12) -> 0 | G13: =SUM(G12:G12) -> 0 | H13: =SUM(H12:H12) -> 0 | I13: =SUM(I12:I12) -> 0 | J13: =E13-H13 -> 0 | L13: ${summary.quarterTotalAmount?summary.quarterTotalAmount:0.00}
A15: C. OOE | F15: Cumulative Disbursement up to Previous Quarter (S$) | G15: Claim Amount for Current Quarter (S$) | H15: Cumulative Claim Amount To-Date (S$) | I15: Cumulative Claims Amount To-Date (S$) | J15: Remaining Grant Balance (S$) | L15: ${date.formatter("MMM").format(claim.items[0].startDate)} - ${date.formatter("MMM yy").format(claim.items[0].endDate)} (S$)
A16: Item Code | B16: Description | C16: Quantity | D16: Unit Cost | E16: Subtotal (S$)
D17: (S$)
A18: C-${index+1} | B18: ${summary.internalOrderCode.substring(15,20)} | E18: ${summary.approvedBudget} | F18: ${index==0?summary.groupedTransactions[0].transactions[0].claimSummary.cumExpenseUptoPrevPeriod:""} | G18: ${summary.quarterAdjustedTotal} | H18: =SUM(F18:G18) -> 0 | J18: =E18-H18 -> #VALUE!
A19: Total | E19: ='Summ of Fund Requisitions'!B25 -> 0 | F19: =SUM(F18:F18) -> 0 | G19: =SUM(G18:G18) -> 0 | H19: =SUM(H18:H18) -> 0 | I19: =SUM(I18:I18) -> 0 | J19: =E19-H19 -> 0 | L19: ${summary.quarterTotalAmount?summary.quarterTotalAmount:0.00}
A21: D. OVERSEAS TRAVEL | F21: Cumulative Disbursement up to Previous Quarter (S$) | G21: Claim Amount for Current Quarter (S$) | H21: Cumulative Claim Amount To-Date (S$) | I21: Cumulative Claims Amount To-Date (S$) | J21: Remaining Grant Balance (S$) | L21: ${date.formatter("MMM").format(claim.items[0].startDate)} - ${date.formatter("MMM yy").format(claim.items[0].endDate)} (S$)
A22: Item Code | B22: Description | C22: Quantity | D22: Unit Cost | E22: Subtotal (S$)
D23: (S$)
A24: D-${index+1} | B24: ${summary.internalOrderCode.substring(15,20)} | E24: ${summary.approvedBudget} | F24: ${index==0?summary.groupedTransactions[0].transactions[0].claimSummary.cumExpenseUptoPrevPeriod:""} | G24: ${summary.quarterAdjustedTotal} | H24: =SUM(F24:G24) -> 0 | J24: =E24-H24 -> #VALUE!
A25: Total | E25: ='Summ of Fund Requisitions'!B28 -> 0 | F25: =SUM(F24:F24) -> 0 | G25: =SUM(G24:G24) -> 0 | H25: =SUM(H24:H24) -> 0 | I25: =SUM(I24:I24) -> 0 | J25: =E25-H25 -> 0 | L25: ${summary.quarterTotalAmount?summary.quarterTotalAmount:0.00}
A27: E. RESEARCH SCHOLARSHIP | F27: Cumulative Disbursement up to Previous Quarter (S$) | G27: Claim Amount for Current Quarter (S$) | H27: Cumulative Claim Amount To-Date (S$) | I27: Cumulative Claims Amount To-Date (S$) | J27: Remaining Grant Balance (S$) | L27: ${date.formatter("MMM").format(claim.items[0].startDate)} - ${date.formatter("MMM yy").format(claim.items[0].endDate)} (S$)
A28: Item Code | B28: Description | C28: Quantity | D28: Unit Cost | E28: Subtotal (S$)
D29: (S$)
A30: E-${index+1} | B30: ${summary.internalOrderCode.substring(15,20)} | E30: ${summary.approvedBudget} | F30: ${index==0?summary.groupedTransactions[0].transactions[0].claimSummary.cumExpenseUptoPrevPeriod:""} | G30: ${summary.quarterAdjustedTotal} | H30: =SUM(F30:G30) -> 0 | J30: =E30-H30 -> #VALUE!
A31: Total | E31: ='Summ of Fund Requisitions'!B31 -> 0 | F31: =SUM(F30:F30) -> 0 | G31: =SUM(G30:G30) -> 0 | H31: =SUM(H30:H30) -> 0 | I31: =SUM(I30:I30) -> 0 | J31: =E31-H31 -> 0 | L31: ${summary.quarterTotalAmount?summary.quarterTotalAmount:0.00}
A33: Description | F33: Awarded Grant Amount | G33: Cumulative Disbursement up to Previous Quarter | H33: Claim Amount for Current Quarter | L33: ${date.formatter("MMM").format(claim.items[0].startDate)} - ${date.formatter("MMM yy").format(claim.items[0].endDate)}
A34: Total (A) + (B) + (C) + (D) + (E) | F34: =E31+E25+E19+E13+E7 -> 0 | G34: =F31+F25+F19+F13+F7 -> 0 | H34: =G31+G25+G19+G13+G7 -> 0 | L34: ${aggregator.sum(claim.items[0].claimSummaryDetails,"quarterTotalAmount")}
A36: Indirect Costs (where applicable) | F36: ='Summ of Fund Requisitions'!B34 -> 0 | G36: ='Summ of Fund Requisitions'!D34 -> 0 | H36: ='Summ of Fund Requisitions'!G33 -> #VALUE! | L36: =ROUND(L34*0.2,2) -> #VALUE!
A38: Grand Total | F38: =SUM(F34:F37) -> 0 | G38: =SUM(G34:G37) -> 0 | H38: =SUM(H34:H37) -> #VALUE! | L38: =L34+L36 -> #VALUE!
A40: As per Summary Page | F40: ='Summ of Fund Requisitions'!B35 -> 0 | G40: ='Summ of Fund Requisitions'!D35 -> 0 | H40: ='Summ of Fund Requisitions'!G35 -> #VALUE!
A42: Difference | F42: =F40-F38 -> 0 | G42: =G40-G38 -> 0 | H42: =H40-H38 -> #VALUE!
L44: $[SUM(U_(M44,L38))]
